Workbook

Sheet reserva-Regla oper propuesta
A1: Paso 1. ¿Dónde deseas recibir tu servicio?
A3: 🏢 En Exentia Spa
A5: 🏠 A Domicilio (Exentia At Home)
A9: Paso 2. ¿Para cuántas personas?
A11: ○ 1 persona
A13: ○ 2 personas
A15: ○ 3 o más personas
A19: Paso 3. Si son 2 o más personas
A21: ¿Desean recibir los servicios al mismo tiempo?
A23: ○ Sí
A25: ○ No
A27: ○ Lo que tenga mejor disponibilidad
... A153: “Podemos atenderlos al mismo tiempo o por turnos. La atención por turnos puede tomar más tiempo, pero puede reducir el costo de traslado, ya que se asignan menos terapeutas al domicilio.”

Sheet consideraciones en agenda 
A1: REGLAS OPERATIVAS PARA CONFIGURACIÓN DE RESERVAS – EXENTIA SPA & EXENTIA AT HOME
A3: 1. RESERVAS EN EXENTIA SPA (LOCAL PLAZA COMERCIAL HIVE)
A5: • Todos los servicios podrán reservarse para el mismo día, sujetos a disponibilidad.
A7: • El sistema deberá mostrar los horarios disponibles con base en la agenda real de cada colaborador.
A9: • Los colaboradores fijos podrán recibir reservas en cualquier horario disponible de su agenda.
A11: • El sistema no deberá limitar reservas por horarios predefinidos de salida si el colaborador tiene disponibilidad para extender su jornada.
A13: • Los complementos podrán agregarse a una reserva existente siempre que exista tiempo disponible en la agenda del colaborador.
A15: 2. RESERVAS EXENTIA AT HOME
A17: • El servicio principal requiere un mínimo de 2 horas de anticipación para reservar.
A19: • Una vez creada la reserva, los complementos podrán agregarse sin que el sistema vuelva a exigir las 2 horas de anticipación. Contamos con servicios que no tienen un clasificacion como complemento pero tambien se pueden vender como facial y depilacion
A21: • El tiempo mínimo de anticipación aplica únicamente al servicio principal de la reserva.
A23: • El sistema deberá considerar tiempos de traslado de acuerdo con la zona asignada.
... A68: Ejemplos:
A70: Categoría | B70: Subcategoría | C70: Servicio | D70: Duración | E70: Precio | G70: Categoría | H70: Subcategoría | I70: Servicio | J70: Duración | K70: Precio | L70: Notas
A71: Masajes | B71: Complementos | C71: Reflexología | D71: 15 min | E71: 250 | G71: Depilación | H71: Depilación con cera | I71: Facial completo | J71: 30 min | K71: 465 | L71: En los servicios de depilacion los minutos cambian dependiendo del genero dama o caballero al igual que el precio del servicio*** y tambien se pueden agregar a los servicios de masaje at home
A72: Masajes | B72: Complementos | C72: Reflexología | D72: 30 min | E72: 450 | G72: Depilación | H72: Depilación con cera | I72: Frente | J72: 5 min | K72: 140
A73: Masajes | B73: Complementos | C73: Craneofacial | D73: 15 min | E73: 250 | G73: Depilación | H73: Depilación con cera | I73: Sien | J73: 5 min | K73: 140
A74: Masajes | B74: Complementos | C74: Drenaje Linfático | D74: 30 min | E74: 650 | G74: Depilación | H74: Depilación con cera | I74: Cejas | J74: 10 min | K74: 140
A75: Masajes | B75: Complementos | C75: Head Massage | D75: 30 min | E75: 550 | G75: Depilación | H75: Depilación con cera | I75: Perfilado de cejas | J75: 20 min | K75: 230
A76: Masajes | B76: Complementos | C76: Masaje Tiempo Extra | D76: 15 min | E76: 250 | G76: Depilación | H76: Depilación con cera | I76: Bozo | J76: 5 min | K76: 140
A77: Masajes | B77: Complementos | C77: Masaje Tiempo Extra | D77: 30 min | E77: 450 | G77: Depilación | H77: Depilación con cera | I77: Nariz | J77: 5 min | K77: 135
A78: Faciales | B78: Complementos | C78: Craneofacial | D78: 30 min | E78: 450 | G78: Depilación | H78: Depilación con cera | I78: Pómulos | J78: 5 min | K78: 140
A79: Faciales | B79: Complementos | C79: Facial Express for Her | D79: 30 min | E79: 650 | G79: Depilación | H79: Depilación con cera | I79: Patillas | J79: 5 min | K79: 140
A80: Faciales | B80: Complementos | C80: Facial Express for Him | D80: 30 min | E80: 650 | G80: Depilación | H80: Depilación con cera | I80: Barba | J80: 5 min | K80: 140
A81: Faciales | B81: Complementos | C81: Aplicación de mascarilla facial | D81: 15 min | E81: 350 | G81: Depilación | H81: Depilación con cera | I81: Nuca | J81: 10 min | K81: 155
G82: Depilación | H82: Depilación con cera | I82: Axilas | J82: 20 min | K82: 175
G83: Depilación | H83: Depilación con cera | I83: Brasileño | J83: 35 min | K83: 600
G84: Depilación | H84: Depilación con cera | I84: Resaque Bikini | J84: 25 min | K84: 290
G85: Depilación | H85: Depilación con cera | I85: Resaque Bikini Profundo | J85: 25 min | K85: 340
G86: Depilación | H86: Depilación con cera | I86: Línea Interglútea | J86: 5 min | K86: 155
G87: Depilación | H87: Depilación con cera | I87: Glúteos | J87: 25 min | K87: 425
G88: Depilación | H88: Depilación con cera | I88: Piernas | J88: 30 min | K88: 510
G89: Depilación | H89: Depilación con cera | I89: 1/2 Piernas | J89: 25 min | K89: 385
G90: Depilación | H90: Depilación con cera | I90: Brazos | J90: 30 min | K90: 405
G91: Depilación | H91: Depilación con cera | I91: 1/2 Brazos | J91: 25 min | K91: 335
G92: Depilación | H92: Depilación con cera | I92: Espalda | J92: 30 min | K92: 445
G93: Depilación | H93: Depilación con cera | I93: Espalda Baja | J93: 15 min | K93: 200
... G97: Depilación | H97: Depilación con cera | I97: Cuerpo Completo | J97: 120 min | K97: 2050
A100: • Los complementos no deberán generar una nueva restricción de anticipación.
A102: 7. DISPONIBILIDAD A DOMICILIO
...

Sheet catalogo de productos
A1: Ubicación | B1: Categoría | C1: Subcategoría | D1: Servicio | E1: Status | F1: Modalidad | G1: Duración | H1: Precio | I1: Notas | J1: Unnamed: 8 | K1: Unnamed: 9 | L1: Anticipación recomendada para reserva | M1: Disponible a domicilio | N1: Consideraciones operativas
A2: 🏢 En Exentia Spa/🏠 A Domicilio (Exentia At Home) | B2: Masajes | C2: Terapias de masajes | D2: Masaje Exentia | F2: Individual | G2: 60 min | H2: 1550 | L2: Exentia Spa/At Home: mínimo 2 horas antes (solo servicio principal). Complementos pueden agregarse en sitio, facial, depilacion, si es en exentia spa puede agregar cualquier servicio activo disponible | M2: Sí | N2: No bloquear complementos agregados en sitio; validar disponibilidad del terapeuta.
A3: 🏢 En Exentia Spa/🏠 A Domicilio (Exentia At Home) | B3: Masajes | C3: Terapias de masajes | D3: Masaje Exentia | F3: Individual | G3: 90 min | H3: 2000 | L3: Exentia Spa/At Home: mínimo 2 horas antes (solo servicio principal). Complementos pueden agregarse en sitio, facial, depilacion, si es en exentia spa puede agregar cualquier servicio activo disponible | M3: Sí | N3: No bloquear complementos agregados en sitio; validar disponibilidad del terapeuta.
A4: 🏢 En Exentia Spa/🏠 A Domicilio (Exentia At Home) | B4: Masajes | C4: Terapias de masajes | D4: Masaje Exentia | F4: Pareja | G4: 60 min | H4: 3100 | L4: Exentia Spa/At Home: mínimo 2 horas antes (solo servicio principal). Complementos pueden agregarse en sitio, facial, depilacion, si es en exentia spa puede agregar cualquier servicio activo disponible | M4: Sí | N4: No bloquear complementos agregados en sitio; validar disponibilidad del terapeuta.
A5: 🏢 En Exentia Spa/🏠 A Domicilio (Exentia At Home) | B5: Masajes | C5: Terapias de masajes | D5: Masaje Exentia | F5: Pareja | G5: 90 min | H5: 4000 | L5: Exentia Spa/At Home: mínimo 2 horas antes (solo servicio principal). Complementos pueden agregarse en sitio, facial, depilacion, si es en exentia spa puede agregar cualquier servicio activo disponible | M5: Sí | N5: No bloquear complementos agregados en sitio; validar disponibilidad del terapeuta.
A6: 🏢 En Exentia Spa/🏠 A Domicilio (Exentia At Home) | B6: Masajes | C6: Terapias de masajes | D6: Masaje Exentia Plus Personalizado | F6: Individual | G6: 90 min | H6: 2140 | L6: Exentia Spa/At Home: mínimo 2 horas antes (solo servicio principal). Complementos pueden agregarse en sitio, facial, depilacion, si es en exentia spa puede agregar cualquier servicio activo disponible | M6: Sí | N6: No bloquear complementos agregados en sitio; validar disponibilidad del terapeuta.
A7: 🏢 En Exentia Spa/🏠 A Domicilio (Exentia At Home) | B7: Masajes | C7: Terapias de masajes | D7: Masaje Exentia Plus Personalizado | F7: Pareja | G7: 90 min | H7: 4280 | L7: Exentia Spa/At Home: mínimo 2 horas antes (solo servicio principal). Complementos pueden agregarse en sitio, facial, depilacion, si es en exentia spa puede agregar cualquier servicio activo disponible | M7: Sí | N7: No bloquear complementos agregados en sitio; validar disponibilidad del terapeuta.
A8: 🏢 En Exentia Spa/🏠 A Domicilio (Exentia At Home) | B8: Masajes | C8: Terapias de masajes | D8: Masaje Tejido Profundo | F8: Individual | G8: 60 min | H8: 1550 | L8: Exentia Spa/At Home: mínimo 2 horas antes (solo servicio principal). Complementos pueden agregarse en sitio, facial, depilacion, si es en exentia spa puede agregar cualquier servicio activo disponible | M8: Sí | N8: No bloquear complementos agregados en sitio; validar disponibilidad del terapeuta.
A9: 🏢 En Exentia Spa/🏠 A Domicilio (Exentia At Home) | B9: Masajes | C9: Terapias de masajes | D9: Masaje Tejido Profundo | F9: Individual | G9: 90 min | H9: 2000 | L9: Exentia Spa/At Home: mínimo 2 horas antes (solo servicio principal). Complementos pueden agregarse en sitio, facial, depilacion, si es en exentia spa puede agregar cualquier servicio activo disponible | M9: Sí | N9: No bloquear complementos agregados en sitio; validar disponibilidad del terapeuta.
A10: 🏢 En Exentia Spa/🏠 A Domicilio (Exentia At Home) | B10: Masajes | C10: Terapias de masajes | D10: Masaje Tejido Profundo | F10: Pareja | G10: 60 min | H10: 3100 | L10: Exentia Spa/At Home: mínimo 2 horas antes (solo servicio principal). Complementos pueden agregarse en sitio, facial, depilacion, si es en exentia spa puede agregar cualquier servicio activo disponible | M10: Sí | N10: No bloquear complementos agregados en sitio; validar disponibilidad del terapeuta.
A11: 🏢 En Exentia Spa/🏠 A Domicilio (Exentia At Home) | B11: Masajes | C11: Terapias de masajes | D11: Masaje Tejido Profundo | F11: Pareja | G11: 90 min | H11: 4000 | L11: Exentia Spa/At Home: mínimo 2 horas antes (solo servicio principal). Complementos pueden agregarse en sitio, facial, depilacion, si es en exentia spa puede agregar cualquier servicio activo disponible | M11: Sí | N11: No bloquear complementos agregados en sitio; validar disponibilidad del terapeuta.
A12: 🏢 En Exentia Spa/🏠 A Domicilio (Exentia At Home) | B12: Masajes | C12: Terapias de masajes | D12: Masaje Terapéutico | F12: Individual | G12: 60 min | H12: 1550 | L12: Exentia Spa/At Home: mínimo 2 horas antes (solo servicio principal). Complementos pueden agregarse en sitio, facial, depilacion, si es en exentia spa puede agregar cualquier servicio activo disponible | M12: Sí | N12: No bloquear complementos agregados en sitio; validar disponibilidad del terapeuta.
A13: 🏢 En Exentia Spa/🏠 A Domicilio (Exentia At Home) | B13: Masajes | C13: Terapias de masajes | D13: Masaje Terapéutico | F13: Individual | G13: 90 min | H13: 2000 | L13: Exentia Spa/At Home: mínimo 2 horas antes (solo servicio principal). Complementos pueden agregarse en sitio, facial, depilacion, si es en exentia spa puede agregar cualquier servicio activo disponible | M13: Sí | N13: No bloquear complementos agregados en sitio; validar disponibilidad del terapeuta.
... A15: 🏢 En Exentia Spa/🏠 A Domicilio (Exentia At Home) | B15: Masajes | C15: Terapias de masajes | D15: Masaje Terapéutico | F15: Pareja | G15: 90 min | H15: 4000 | L15: Exentia Spa/At Home: mínimo 2 horas antes (solo servicio principal). Complementos pueden agregarse en sitio, facial, depilacion, si es en exentia spa puede agregar cualquier servicio activo disponible | M15: Sí | N15: No bloquear complementos agregados en sitio; validar disponibilidad del terapeuta.
B16: Masajes | C16: Terapias de masajes | D16: Masaje Terapéutico Ice Calm | E16: Inactivo | F16: Individual | G16: 60 min | H16: 2450 | L16: Exentia Spa/At Home: mínimo 2 horas antes (solo servicio principal). Complementos pueden agregarse en sitio, facial, depilacion, si es en exentia spa puede agregar cualquier servicio activo disponible | M16: Sí | N16: No bloquear complementos agregados en sitio; validar disponibilidad del terapeuta.
B17: Masajes | C17: Terapias de masajes | D17: Turbante Ice Calm | E17: Inactivo | F17: Individual | G17: 60 min | H17: 750 | L17: Exentia Spa/At Home: mínimo 2 horas antes (solo servicio principal). Complementos pueden agregarse en sitio, facial, depilacion, si es en exentia spa puede agregar cualquier servicio activo disponible | M17: Sí | N17: No bloquear complementos agregados en sitio; validar disponibilidad del terapeuta.
A18: 🏢 En Exentia Spa | B18: Masajes | C18: Terapias de masajes | D18: Masaje de Espalda | F18: Individual | G18: 30 min | H18: 790 | L18: Exentia Spa/At Home: mínimo 2 horas antes (solo servicio principal). Complementos pueden agregarse en sitio, facial, depilacion, si es en exentia spa puede agregar cualquier servicio activo disponible | M18: No | N18: No bloquear complementos agregados en sitio; validar disponibilidad del terapeuta.
A19: 🏢 En Exentia Spa/🏠 A Domicilio (Exentia At Home) | B19: Masajes | C19: Terapias de masajes | D19: Masaje Terapéutico con Ventosas | F19: Individual | G19: 90 min | H19: 2450 | L19: Exentia Spa/At Home: mínimo 2 horas antes (solo servicio principal). Complementos pueden agregarse en sitio, facial, depilacion, si es en exentia spa puede agregar cualquier servicio activo disponible | M19: Sí | N19: No bloquear complementos agregados en sitio; validar disponibilidad del terapeuta.
A20: 🏢 En Exentia Spa/🏠 A Domicilio (Exentia At Home) | B20: Masajes | C20: Terapias de masajes | D20: Masaje Terapéutico con Ventosas | F20: Pareja | G20: 90 min | H20: 4900 | L20: Exentia Spa/At Home: mínimo 2 horas antes (solo servicio principal). Complementos pueden agregarse en sitio, facial, depilacion, si es en exentia spa puede agregar cualquier servicio activo disponible | M20: Sí | N20: No bloquear complementos agregados en sitio; validar disponibilidad del terapeuta.
A21: 🏢 En Exentia Spa/🏠 A Domicilio (Exentia At Home) | B21: Masajes | C21: Terapias de masajes | D21: Masaje Terapéutico de Piedras Calientes | F21: Individual | G21: 90 min | H21: 2450 | L21: Exentia Spa/At Home: mínimo 2 horas antes (solo servicio principal). Complementos pueden agregarse en sitio, facial, depilacion, si es en exentia spa puede agregar cualquier servicio activo disponible | M21: Sí | N21: No bloquear complementos agregados en sitio; validar disponibilidad del terapeuta.
A22: 🏢 En Exentia Spa/🏠 A Domicilio (Exentia At Home) | B22: Masajes | C22: Terapias de masajes | D22: Masaje Terapéutico de Piedras Calientes | F22: Pareja | G22: 90 min | H22: 4900 | L22: Exentia Spa/At Home: mínimo 2 horas antes (solo servicio principal). Complementos pueden agregarse en sitio, facial, depilacion, si es en exentia spa puede agregar cualquier servicio activo disponible | M22: Sí | N22: No bloquear complementos agregados en sitio; validar disponibilidad del terapeuta.
A23: 🏢 En Exentia Spa/🏠 A Domicilio (Exentia At Home) | B23: Masajes | C23: Terapias de masajes | D23: Masaje Terapéutico Integral | F23: Individual | G23: 90 min | H23: 2450 | L23: Exentia Spa/At Home: mínimo 2 horas antes (solo servicio principal). Complementos pueden agregarse en sitio, facial, depilacion, si es en exentia spa puede agregar cualquier servicio activo disponible | M23: Sí | N23: No bloquear complementos agregados en sitio; validar disponibilidad del terapeuta.
A24: 🏢 En Exentia Spa/🏠 A Domicilio (Exentia At Home) | B24: Masajes | C24: Terapias de masajes | D24: Masaje Terapéutico Plus | F24: Individual | G24: 90 min | H24: 2450 | L24: Exentia Spa/At Home: mínimo 2 horas antes (solo servicio principal). Complementos pueden agregarse en sitio, facial, depilacion, si es en exentia spa puede agregar cualquier servicio activo disponible | M24: Sí | N24: No bloquear complementos agregados en sitio; validar disponibilidad del terapeuta.
A25: 🏢 En Exentia Spa/🏠 A Domicilio (Exentia At Home) | B25: Masajes | C25: Terapias de masajes | D25: Drenaje Linfático | F25: Individual | G25: 60 min | H25: 1690 | L25: Exentia Spa/At Home: mínimo 2 horas antes (solo servicio principal). Complementos pueden agregarse en sitio, facial, depilacion, si es en exentia spa puede agregar cualquier servicio activo disponible | M25: Sí | N25: No bloquear complementos agregados en sitio; validar disponibilidad del terapeuta.
A26: 🏢 En Exentia Spa/🏠 A Domicilio (Exentia At Home) | B26: Masajes | C26: Terapias de masajes | D26: Drenaje Linfático | F26: Individual | G26: 90 min | H26: 2350 | L26: Exentia Spa/At Home: mínimo 2 horas antes (solo servicio principal). Complementos pueden agregarse en sitio, facial, depilacion, si es en exentia spa puede agregar cualquier servicio activo disponible | M26: Sí | N26: No bloquear complementos agregados en sitio; validar disponibilidad del terapeuta.
A27: 🏢 En Exentia Spa/🏠 A Domicilio (Exentia At Home) | B27: Masajes | C27: Terapias de masajes | D27: Drenaje Linfático | F27: Pareja | G27: 60 min | H27: 3380 | L27: Exentia Spa/At Home: mínimo 2 horas antes (solo servicio principal). Complementos pueden agregarse en sitio, facial, depilacion, si es en exentia spa puede agregar cualquier servicio activo disponible | M27: Sí | N27: No bloquear complementos agregados en sitio; validar disponibilidad del terapeuta.
A28: 🏢 En Exentia Spa/🏠 A Domicilio (Exentia At Home) | B28: Masajes | C28: Terapias de masajes | D28: Drenaje Linfático | F28: Pareja | G28: 90 min | H28: 4700 | L28: Exentia Spa/At Home: mínimo 2 horas antes (solo servicio principal). Complementos pueden agregarse en sitio, facial, depilacion, si es en exentia spa puede agregar cualquier servicio activo disponible | M28: Sí | N28: No bloquear complementos agregados en sitio; validar disponibilidad del terapeuta.
A29: 🏢 En Exentia Spa | B29: Masajes | C29: Terapias de masajes | D29: Reflexología Podal | F29: Individual | G29: 60 min | H29: 750 | L29: Exentia Spa mínimo 2 horas antes (solo servicio de masajes, facial y depilacion) todos los servicios activos dependiendo de la disponibildad | M29: No | N29: No bloquear complementos agregados en sitio; validar disponibilidad del terapeuta.
... A50: 🏢 En Exentia Spa | B50: Uñas | C50: Manicure | D50: Manicura Exentia Caballero | F50: Individual | G50: 60 min | H50: 350 | L50: Mismo día según disponibilidad. | M50: No | N50: Permitir reserva simultánea de manicura y pedicura si existen mas técnicas en uñas disponibles.
A51: 🏢 En Exentia Spa | B51: Uñas | C51: Pedicure | D51: Pedicura Exentia con Esmalte | F51: Individual | G51: 70 min | H51: 580 | I51: Hidromasaje Spa | L51: Mismo día según disponibilidad. | M51: No | N51: Permitir reserva simultánea de manicura y pedicura si existen mas técnicas en uñas disponibles.
A52: 🏢 En Exentia Spa | B52: Uñas | C52: Pedicure | D52: Pedicura Exentia con Gel | F52: Individual | G52: 90 min | H52: 690 | I52: Hidromasaje Spa | L52: Mismo día según disponibilidad. | M52: No | N52: Permitir reserva simultánea de manicura y pedicura si existen mas técnicas en uñas disponibles.
A53: 🏢 En Exentia Spa | B53: Uñas | C53: Pedicure | D53: Pedicura Exentia Caballero | F53: Individual | G53: 50 min | H53: 490 | I53: Hidromasaje Spa | L53: Mismo día según disponibilidad. | M53: No | N53: Permitir reserva simultánea de manicura y pedicura si existen mas técnicas en uñas disponibles.
A54: 🏢 En Exentia Spa | B54: Uñas | C54: Corte | D54: Corte de Uñas | F54: Manos | G54: 25 min | H54: 120 | L54: Mismo día según disponibilidad. | M54: No | N54: Permitir reserva simultánea de manicura y pedicura si existen mas técnicas en uñas disponibles.
A55: 🏢 En Exentia Spa | B55: Uñas | C55: Corte | D55: Corte de Uñas | F55: Pies | G55: 25 min | H55: 150 | L55: Mismo día según disponibilidad. | M55: No | N55: Permitir reserva simultánea de manicura y pedicura si existen mas técnicas en uñas disponibles.
A56: 🏢 En Exentia Spa | B56: Uñas | C56: Color | D56: Esmaltado Regular | F56: Individual | G56: 30 min | H56: 180 | L56: Mismo día según disponibilidad. | M56: No | N56: Permitir reserva simultánea de manicura y pedicura si existen mas técnicas en uñas disponibles.
A57: 🏢 En Exentia Spa | B57: Uñas | C57: Color | D57: Esmaltado Regular Infantil | F57: Individual | G57: 30 min | H57: 140 | L57: Mismo día según disponibilidad. | M57: No | N57: Permitir reserva simultánea de manicura y pedicura si existen mas técnicas en uñas disponibles.
A58: 🏢 En Exentia Spa | B58: Uñas | C58: Color | D58: Esmaltado Francés | F58: Individual | G58: 50 min | H58: 195 | L58: Mismo día según disponibilidad. | M58: No | N58: Permitir reserva simultánea de manicura y pedicura si existen mas técnicas en uñas disponibles.
A59: 🏢 En Exentia Spa | B59: Uñas | C59: Color | D59: Gel Semipermanente | F59: Individual | G59: 50 min | H59: 290 | L59: Mismo día según disponibilidad. | M59: No | N59: Permitir reserva simultánea de manicura y pedicura si existen mas técnicas en uñas disponibles.
A60: 🏢 En Exentia Spa | B60: Uñas | C60: Acrílico / Polygel | D60: Uñas Acrílicas Tip No. 3 | F60: Cover Natural | G60: 90 min | H60: 550 | L60: Mismo día según disponibilidad. | M60: No | N60: Permitir reserva simultánea de manicura y pedicura si existen mas técnicas en uñas disponibles.
A61: 🏢 En Exentia Spa | B61: Uñas | C61: Acrílico / Polygel | D61: Uñas Acrílicas Tip No. 3 con Gel | F61: Incluye marca premium | G61: 120 min | H61: 650 | L61: Mismo día según disponibilidad. | M61: No | N61: Permitir reserva simultánea de manicura y pedicura si existen mas técnicas en uñas disponibles.
...

Sheet Promociones
A4: Ubicación | B4: Promocion
A5: 🏢 En Exentia Spa | B5: DIVA SPA | D5: Precio promo | E5: Ahorro | F5: % descuento
B6: Masaje Relajante + facial | C6: =1550+1290 -> 2840 | D6: =1550+466 -> 2016
B7: Manicura con Gel | C7: 590 | D7: =+C7 -> 590
B8: Pedicura con Gel | C8: 690 | D8: =+C8 -> 690
B10: Precio Regular | C10: =SUM(C6:C9) -> 4120 | D10: =SUM(D6:D8) -> 3296 | E10: =C10-D10 -> 824 | F10: =+E10/C10 -> 0.2
B11: Total | C11: =+D10 -> 3296
A15: Ubicación | B15: Promocion | C15: nota: esta promocion reemplaza a la promocion 2 mas 1
B16: RITUAL EXENTIA | C16: Duracion de tu servicio | D16: Precio de lista | E16: PROMOCION EN EXENTIA | F16: Ahorro | G16: % desc
B17: Facial + Masaje | C17: 60 min
B18: Escoge tu masaje favorito y facial: la combinacion perfecta para desconectarte y renovar tu energía
B19: MASAJE EXENTIA + Facial 60 min | D19: 1550 | E19: 1190
D20: 1290 | E20: 990
A21: 🏢 En Exentia Spa | B21: Total s/transporte | D21: =SUM(D19:D20) -> 2840 | E21: =SUM(E19:E20) -> 2180 | F21: =D21-E21 -> 660 | G21: =+F21/D21 -> 0.23239437
B22: Transporte desde: | E22: 0
B23: Zona 1 | D23: =+Zonas!K5 -> 250
B24: Zona 2 | D24: =+Zonas!K6 -> 350
B25: Zona 3 | D25: =Zonas!K7 -> 400
A26: 🏠 A Domicilio (Exentia At Home) | B26: Total c/transporte zona 2 | D26: =E21+D24 -> 2530
B30: RITUAL EXENTIA | C30: Duracion de tu servicio | E30: PROMOCION EN EXENTIA | F30: Ahorro | G30: % desc
B31: Facial + Masaje | C31: 90 min
B32: Escoge tu masaje favorito y facial: la combinacion perfecta para desconectarte y renovar tu energía
B33: MASAJE EXENTIA 90 MIN | D33: 2000 | E33: 1390
B34: FACIAL ORGANICO | D34: 1290 | E34: 1190
A35: 🏢 En Exentia Spa | B35: Total s/transporte | D35: =SUM(D33:D34) -> 3290 | E35: =SUM(E33:E34) -> 2580 | F35: =D35-E35 -> 710 | G35: =+F35/D35 -> 0.21580547
B36: Transporte desde: | E36: 0
B37: Zona 1 | D37: =+Zonas!K5 -> 250
B38: Zona 2 | D38: =+Zonas!K6 -> 350
B39: Zona 3 | D39: =+Zonas!K7 -> 400
A40: 🏠 A Domicilio (Exentia At Home) | B40: Total c/transporte zona 1 | D40: =+E35+D37 -> 2830
B44: RITUAL CABALLERO | C44: Duracion de tu servicio
B45: Masaje + Corte + Servicio de barberia | C45: 125 min | D45: 1550 | E45: 1235
D46: 350 | E46: 350
D47: 200 | E47: 200
D48: =SUM(D45:D47) -> 2100 | E48: =SUM(E45:E47) -> 1785 | F48: =D48-E48 -> 315 | G48: =+F48/D48 -> 0.15
A49: 🏢 En Exentia Spa | B49: Total | D49: =+E48 -> 1785

Sheet Zonas
K4: COSTO DE TRASLADO POR CADA TERAPEUTA QUE DARÁ SERVICIO A DOMICILIO
J5: ZONA 1 (COLOR VERDE) | K5: 250 | L5: Centro, downtown, Puerto Cancun
J6: ZONA 2 (COLOR AMARILLA) | K6: 350 | L6: Zona Hotelera de 0 KM hasta 12.5 km, Av. Huayacan
J7: ZONA 3 (COLOR ROJO) | K7: 400 | L7: Zona Hotelera de 12.5 KM hasta 22 km, area del aeropuerto
